Workbook
Name UPDATE: 'Data Sheet'!$E$1

Sheet DCF
B1: HINDUSTAN UNILEVER
B7: DCF VALUATION
B10: Calculation for PV of FCFF | D10: ='[1]Intrinsic growth'!$I$2 -> 45717 | E10: =D10+365 -> 46082 | F10: =E10+365 -> 46447 | G10: =F10+366 -> 46813 | H10: =G10+365 -> 47178 | I10: =H10+365 -> 47543
B12: EBIT | D12: ='Intrinsic growth'!I40 -> 13488 | E12: =D12*(1+$C$22) -> 14150.261 | F12: =E12*(1+$C$22) -> 14845.039 | G12: =F12*(1+$C$22) -> 15573.93 | H12: =G12*(1+$C$22) -> 16338.61 | I12: =H12*(1+$C$22) -> 17140.836
B13: TAX | D13: 0.25 | E13: =D13 -> 0.25 | F13: =E13 -> 0.25 | G13: =F13 -> 0.25 | H13: =G13 -> 0.25 | I13: =H13 -> 0.25
B14: EBIT(1-T) | D14: =D12*(1-D13) -> 10116 | E14: =E12*(1-E13) -> 10612.696 | F14: =F12*(1-F13) -> 11133.779 | G14: =G12*(1-G13) -> 11680.448 | H14: =H12*(1-H13) -> 12253.957 | I14: =I12*(1-I13) -> 12855.627
B15: REINVESTMENT RATE | D15: ='Intrinsic growth'!I59 -> 0.110712 | E15: =($I$15-$D$15)/5+D15 -> 0.19687011 | F15: =($I$15-$D$15)/5+E15 -> 0.28302822 | G15: =($I$15-$D$15)/5+F15 -> 0.36918633 | H15: =($I$15-$D$15)/5+G15 -> 0.45534444 | I15: 0.54150255
B16: FCFF | D16: =D14*(1-D15) -> 8996.0375 | E16: =E14*(1-E15) -> 8523.3731 | F16: =F14*(1-F15) -> 7982.6054 | G16: =G14*(1-G15) -> 7368.186 | H16: =H14*(1-H15) -> 6674.1861 | I16: =I14*(1-I15) -> 5894.2721
B17: MID YEAR CONVENTION | E17: 0.5 | F17: =E17+1 -> 1.5 | G17: =F17+1 -> 2.5 | H17: =G17+1 -> 3.5 | I17: =H17+1 -> 4.5
B18: DISCOUNT RATE | E18: =1/((1+$C$24)^E17) -> 0.94240961 | F18: =1/((1+$C$24)^F17) -> 0.83698777 | G18: =1/((1+$C$24)^G17) -> 0.74335886 | H18: =1/((1+$C$24)^H17) -> 0.66020367 | I18: =1/((1+$C$24)^I17) -> 0.58635055
B20: PV OF FCFF | E20: =E16*E18 -> 8032.5087 | F20: =F16*F18 -> 6681.3431 | G20: =G16*G18 -> 5477.2063 | H20: =H16*H18 -> 4406.3221 | I20: =I16*I18 -> 3456.1097
B22: EXPECTED GROWTH | C22: 0.0491
B23: TERMINAL GROWTH | C23: 0.05
B24: WACC | C24: =WACC!I42 -> 0.12595385
B26: Calculation for Terminal Value
B28: FCFF(n+1) | C28: =I16*(1+C23) -> 6188.9857
B29: WACC | C29: =C24 -> 0.12595385
B30: TERMINAL GROWTH RATE | C30: =C23 -> 0.05
B31: TERMINAL VALUE | C31: =C28/(C29-C30) -> 81483.5
B33: Calculation for Equity Value Per Share
B35: PV OF FCFFs | C35: =SUM(E20:I20) -> 28053.49
B36: TERMINAL VALUE | C36: =C31 -> 81483.5
B37: PV OF TERMINAL VALUE | C37: =C36*I18 -> 47777.896
B38: ENTERPRISE VALUE | C38: =C37+C35 -> 75831.386
B40: ADD: CASH | C40: ='RAW FS'!N41 -> 7554
B41: LESS: DEBT | C41: =SUM('RAW FS'!N9:N10) -> 1
B43: EQUITY VALUE | C43: =C38+C40-C41 -> 83384.386
B44: NO. OF SHARES | C44: ='Data Sheet'!B6 -> 234.95913
B45: EQUITY VALUE PER SHARE | C45: =C43/C44 -> 354.8889
B47: SHARE PRICE | C47: 2166
B48: PREMIUM/DISCOUNT | C48: =C47/C45 -> 6.1033185

Sheet Relative Valuation
B1: HINDUSTAN UNILEVER
B5: Amount in Crores
B6: Comparable Company Valuation
D8: Market Share | J8: Financials | N8: Valuation
B9: Company | C9: Ticker | D9: Share Price | E9: Share Outstanding | F9: Equity Value | G9: Net Debt | H9: Enterprise Value | J9: Revenue | K9: EBITDA | L9: Net Income | N9: EV/REVENUE | O9: EV/EBITDA | P9: P/E
B10: Hind. Unilever | C10: HINDUNILVR | D10: ='Market Data'!D3 -> 2155.3 | E10: ='Market Data'!E3 -> 234.96 | F10: ='Market Data'!F3 -> 506409.29 | G10: ='Market Data'!I3 -> -5779 | H10: ='Market Data'!J3 -> 500630.29 | J10: ='Market Data'!K3 -> 63121 | K10: ='Market Data'!M3 -> 14568.327 | L10: ='Market Data'!N3 -> 14540 | N10: =$H10/J10 -> 7.9312794 | O10: =$H10/K10 -> 34.364296 | P10: =F10/L10 -> 34.828699
B11: ITC | C11: ITC | D11: ='Market Data'!D4 -> 304.25 | E11: ='Market Data'!E4 -> 1252.95 | F11: ='Market Data'!F4 -> 381210.04 | G11: ='Market Data'!I4 -> -3649.39 | H11: ='Market Data'!J4 -> 377560.65 | J11: ='Market Data'!K4 -> 75323.34 | K11: ='Market Data'!M4 -> 25399.03 | L11: ='Market Data'!N4 -> 35356.29 | N11: =$H11/J11 -> 5.0125319 | O11: =$H11/K11 -> 14.86516 | P11: =F11/L11 -> 10.781958
B12: Nestle India | C12: NESTLEIND | D12: ='Market Data'!D5 -> 1249.3 | E12: ='Market Data'!E5 -> 192.83 | F12: ='Market Data'!F5 -> 240902.52 | G12: ='Market Data'!I5 -> 381.2 | H12: ='Market Data'!J5 -> 241283.72 | J12: ='Market Data'!K5 -> 20201.56 | K12: ='Market Data'!M5 -> 4543.3308 | L12: ='Market Data'!N5 -> 3315.9 | N12: =$H12/J12 -> 11.943816 | O12: =$H12/K12 -> 53.107231 | P12: =F12/L12 -> 72.650719
B13: Varun Beverages | C13: VBL | D13: ='Market Data'!D6 -> 431.6 | E13: ='Market Data'!E6 -> 338.21 | F13: ='Market Data'!F6 -> 145971.44 | G13: ='Market Data'!I6 -> 509.69 | H13: ='Market Data'!J6 -> 146481.13 | J13: ='Market Data'!K6 -> 21685.37 | K13: ='Market Data'!M6 -> 5070.0395 | L13: ='Market Data'!N6 -> 3062.04 | N13: =$H13/J13 -> 6.7548364 | O13: =$H13/K13 -> 28.891516 | P13: =F13/L13 -> 47.671303
B14: Britannia Inds. | C14: BRITANNIA | D14: ='Market Data'!D7 -> 5557.5 | E14: ='Market Data'!E7 -> 24.09 | F14: ='Market Data'!F7 -> 133880.17 | G14: ='Market Data'!I7 -> 1883.82 | H14: ='Market Data'!J7 -> 135763.99 | J14: ='Market Data'!K7 -> 17942.67 | K14: ='Market Data'!M7 -> 3310.4226 | L14: ='Market Data'!N7 -> 2416.46 | N14: =$H14/J14 -> 7.5665436 | O14: =$H14/K14 -> 41.011076 | P14: =F14/L14 -> 55.403431
B15: Godrej Consumer | C15: GODREJCP | D15: ='Market Data'!D8 -> 1078.1 | E15: ='Market Data'!E8 -> 102.32 | F15: ='Market Data'!F8 -> 110311.19 | G15: ='Market Data'!I8 -> 3630.43 | H15: ='Market Data'!J8 -> 113941.62 | J15: ='Market Data'!K8 -> 14364.29 | K15: ='Market Data'!M8 -> 2901.5866 | L15: ='Market Data'!N8 -> 1821.6 | N15: =$H15/J15 -> 7.9322836 | O15: =$H15/K15 -> 39.268731 | P15: =F15/L15 -> 60.557308
B16: Tata Consumer | C16: TATACONSUM | D16: ='Market Data'!D9 -> 1093.7 | E16: ='Market Data'!E9 -> 98.96 | F16: ='Market Data'!F9 -> 108232.55 | G16: ='Market Data'!I9 -> -241.75 | H16: ='Market Data'!J9 -> 107990.8 | J16: ='Market Data'!K9 -> 17618.3 | K16: ='Market Data'!M9 -> 2371.4232 | L16: ='Market Data'!N9 -> 1471.5 | N16: =$H16/J16 -> 6.1294678 | O16: =$H16/K16 -> 45.538394 | P16: =F16/L16 -> 73.552533
B17: Marico | C17: MARICO | D17: ='Market Data'!D10 -> 763.25 | E17: ='Market Data'!E10 -> 129.81 | F17: ='Market Data'!F10 -> 99077.482 | G17: ='Market Data'!I10 -> -202 | H17: ='Market Data'!J10 -> 98875.482 | J17: ='Market Data'!K10 -> 10831 | K17: ='Market Data'!M10 -> 1885.6771 | L17: ='Market Data'!N10 -> 1750 | N17: =$H17/J17 -> 9.1289338 | O17: =$H17/K17 -> 52.435002 | P17: =F17/L17 -> 56.615704
B18: United Spirits | C18: UNITDSPR | D18: ='Market Data'!D11 -> 1268.2 | E18: ='Market Data'!E11 -> 72.74 | F18: ='Market Data'!F11 -> 92248.868 | G18: ='Market Data'!I11 -> -1618 | H18: ='Market Data'!J11 -> 90630.868 | J18: ='Market Data'!K11 -> 12069 | K18: ='Market Data'!M11 -> 2200.1787 | L18: ='Market Data'!N11 -> 1720 | N18: =$H18/J18 -> 7.5093933 | O18: =$H18/K18 -> 41.192503 | P18: =F18/L18 -> 53.633063
B19: Dabur India | C19: DABUR | D19: ='Market Data'!D12 -> 435.7 | E19: ='Market Data'!E12 -> 177.37 | F19: ='Market Data'!F12 -> 77280.109 | G19: ='Market Data'!I12 -> 723.42 | H19: ='Market Data'!J12 -> 78003.529 | J19: ='Market Data'!K12 -> 12563.09 | K19: ='Market Data'!M12 -> 2337.991 | L19: ='Market Data'!N12 -> 1819.42 | N19: =$H19/J19 -> 6.2089445 | O19: =$H19/K19 -> 33.363485 | P19: =F19/L19 -> 42.475134
B21: High | N21: =MAX(M10:N19) -> 11.943816 | O21: =MAX(N10:O19) -> 53.107231 | P21: =MAX(O10:P19) -> 73.552533
B22: 75th Percentile | N22: =QUARTILE(N10:N19,3) -> 7.9320326 | O22: =QUARTILE(O10:O19,3) -> 44.451921 | P22: =QUARTILE(P10:P19,3) -> 59.571907
B23: Average | N23: =AVERAGE(N10:N19) -> 7.6118031 | O23: =AVERAGE(O10:O19) -> 38.403739 | P23: =AVERAGE(P10:P19) -> 50.816985
B24: Median | N24: =MEDIAN(N10:N19) -> 7.5379685 | O24: =MEDIAN(O10:O19) -> 40.139904 | P24: =MEDIAN(P10:P19) -> 54.518247
B25: 25th Percentile | N25: =QUARTILE(N10:N19,1) -> 6.3454175 | O25: =QUARTILE(O10:O19,1) -> 33.613688 | P25: =QUARTILE(P10:P19,1) -> 43.774176
B26: Low | N26: =MIN(N10:N19) -> 5.0125319 | O26: =MIN(O10:O19) -> 14.86516 | P26: =MIN(P10:P19) -> 10.781958
B28: ='Data Sheet'!B1&" Comparable Valuation" -> HINDUSTAN UNILEVER LTD Comparable Valuation | N28: EV/REVENUE | O28: EV/EBITDA | P28: P/E
B30: Implied Enterprise Value | N30: =N$24*J10 -> 475804.11 | O30: =O$24*K10 -> 584771.23 | P30: =P$24*L10 -> 792695.31
B31: Net Debt | N31: =$G$10 -> -5779 | O31: =$G$10 -> -5779 | P31: =$G$10 -> -5779
B32: Implied Market Value | N32: =N30+N31 -> 470025.11 | O32: =O30+O31 -> 578992.23 | P32: =P30+P31 -> 786916.31
B33: Shares Outstanding | N33: =$E$10 -> 234.96 | O33: =$E$10 -> 234.96 | P33: =$E$10 -> 234.96
B35: Implied Market Value per Share | N35: =N32/N33 -> 2000.4473 | O35: =O32/O33 -> 2464.2162 | P35: =P32/P33 -> 3349.1501
B37: Source: Screener.in
N38: =IF(N35>$D$10,"Undervalued", "Overvalued") -> Overvalued | O38: =IF(O35>$D$10,"Undervalued", "Overvalued") -> Undervalued | P38: =IF(P35>$D$10,"Undervalued", "Overvalued") -> Undervalued

Sheet WACC
B1: HINDUSTAN UNILEVER
B5: Weighted Average Cost of Capital
B7: All figures are in INR unless stated otherwise
B9: Peer Comps
H10: Debt/ | I10: Debt/ | J10: Levered | K10: Unlevered
B11: Name of the Comp | D11: Country | E11: Total Debt | F11: Total Eq | G11: Tax Rate 1 | H11: Equity | I11: Capital | J11: Beta 2 | K11: Beta 3
B12: Hindustan Unilever | D12: India | E12: 1775 | F12: 504703.92 | G12: 0.25 | H12: =E12/F12 -> 0.0035169134 | I12: =E12/(E12+F12) -> 0.0035045881 | J12: ='Beta Calculation'!K17 -> 0.67290857 | K12: =J12/((1-G12)*H12+1) -> 0.67113831
B13: ITC | D13: India | E13: 362.97 | F13: 380707.86 | G13: 0.25 | H13: =E13/F13 -> 0.00095340821 | I13: =E13/(E13+F13) -> 0.00095250009 | J13: ='Peer Beta'!H113 -> 0.52972916 | K13: =J13/((1-G13)*H13+1) -> 0.52935064
B14: Hindustan Foods | D14: India | E14: 900.81 | F14: 6098.95 | G14: 0.25 | H14: =E14/F14 -> 0.14769919 | I14: =E14/(E14+F14) -> 0.12869156 | J14: ='Peer Beta'!L113 -> 1.0167885 | K14: =J14/((1-G14)*H14+1) -> 0.91538704
B15: Nestle India | D15: India | E15: 476.85 | F15: 240933.28 | G15: 0.25 | H15: =E15/F15 -> 0.0019791786 | I15: =E15/(E15+F15) -> 0.0019752692 | J15: ='Peer Beta'!P113 -> 0.81759042 | K15: =J15/((1-G15)*H15+1) -> 0.8163786
B16: Godrej Consumer | D16: India | E16: 4113.49 | F16: 109865.79 | G16: 0.25 | H16: =E16/F16 -> 0.037441045 | I16: =E16/(E16+F16) -> 0.036089805 | J16: ='Peer Beta'!T113 -> 0.89064309 | K16: =J16/((1-G16)*H16+1) -> 0.86631625
B17: Britannia Inds. | D17: India | E17: 2196.3 | F17: 133956.47 | G17: 0.25 | H17: =E17/F17 -> 0.016395625 | I17: =E17/(E17+F17) -> 0.016131144 | J17: ='Peer Beta'!X113 -> 0.54348 | K17: =J17/((1-G17)*H17+1) -> 0.53687816
G19: Average | H19: =IFERROR(AVERAGE(H12:H17),0) -> 0.034664227 | I19: =IFERROR(AVERAGE(I12:I17),0) -> 0.031224144 | J19: =IFERROR(AVERAGE(J12:J17),0) -> 0.74518995 | K19: =IFERROR(AVERAGE(K12:K17),0) -> 0.72257483
G20: Median | H20: =IFERROR(AVERAGE(H13:H18),0) -> 0.04089369 | I20: =IFERROR(AVERAGE(I13:I18),0) -> 0.036768055 | J20: =IFERROR(AVERAGE(J13:J18),0) -> 0.75964623 | K20: =IFERROR(AVERAGE(K13:K18),0) -> 0.73286214
B24: Cost of Debt | G24: Cost Of Equity
G25: Risk Free Rate | H25: 0.0691
B26: Pre Tax Cost Of Debt | D26: =Historicals!L25/Historicals!L55 -> 0.23968447 | G26: Levered Beta 4 | H26: =I36 -> 0.75533922
B27: Tax Rate | D27: 0.25 | G27: Equity Risk Premium | H27: =Rm!G15-WACC!H25 -> 0.07255
B28: Post Tax Cost Of Debt | D28: =D26*(1-D27) -> 0.17976335 | G28: Cost Of Equity | H28: =H25+H27*H26 -> 0.12389986
B31: Capital Structure | G31: Levered Beta
D33: Current | E33: Target | G33: Comps Median Unlevered Beta | I33: =K20 -> 0.73286214
B34: Total Debt | C34: =E12 -> 1775 | D34: =C34/C36 -> 0.0035045881 | E34: =I20 -> 0.036768055 | G34: Target Debt/ Equity | I34: =H20 -> 0.04089369
B35: Market Capitalization | C35: =F12 -> 504703.92 | D35: =C35/C36 -> 0.99649541 | E35: =1-E34 -> 0.96323195 | G35: Tax Rate | I35: =D27 -> 0.25
B36: Total Capitalization | C36: =SUM(C34:C35) -> 506478.92 | D36: =SUM(D34:D35) -> 1 | E36: =SUM(E34:E35) -> 1 | G36: Levered Beta | I36: =I33*(1+(1-I35)*I34) -> 0.75533922
B38: Debt/Equity | C38: =C34/C35 -> 0.0035169134 | G38: Weighted Average Cost of Capital
G40: Weighted Cost of Debt | I40: =D28*E34 -> 0.0066095487
B41: 1. Tax Rate considered as Marginal Tax Rate for the country | G41: Weighted Cost of Equity | I41: =H28*E35 -> 0.1193443
B42: 2. Levered Beta is based on 5 year monthly data | G42: WACC | I42: =I40+I41 -> 0.12595385
B43: 3. Unlevered Beta = Levered Beta/(1+(1-Tax Rate) x Debt/Equity)
B44: 4. Levered Beta = Unlevered Beta*(1+(1-Tax Rate) x Debt/Equity)

Sheet Forecasting
B1: HINDUSTAN UNILEVER
B5: FORECASTING BASED ON SALES AND EBITDA GROWTH
B8: ='Data Sheet'!$B$1&" - "&'Data Sheet'!A17 -> HINDUSTAN UNILEVER LTD - Sales | G8: ='Data Sheet'!$B$1&" - "&Historicals!B22 -> HINDUSTAN UNILEVER LTD - EBITDA | L8: ='Data Sheet'!$B$1&" - "&Historicals!B42 -> HINDUSTAN UNILEVER LTD - EPS
B9: Year Weight | C9: Year | D9: Sales | E9: Sales Growth | G9: Year Weight | H9: Year | I9: EBITDA | J9: EBITDA Growth | L9: Year Weight | M9: Year | N9: EPS | O9: EPS Growth
B10: 1 | C10: ='Data Sheet'!$B$16 -> 42460 | D10: {=TRANSPOSE('Data Sheet'!B17:K17)} -> 32186 | G10: 1 | H10: ='Data Sheet'!$B$16 -> 42460 | I10: {=TRANSPOSE(Historicals!C22:L22)} -> 5910 | L10: 1 | M10: ='Data Sheet'!$B$16 -> 42460 | N10: {=TRANSPOSE(Historicals!C42:L42)} -> 16.937012
B11: =B10+1 -> 2 | C11: =C10+365 -> 42825 | D11: 33162 | E11: =D11/D10-1 -> 0.030323743 | G11: =G10+1 -> 2 | H11: =H10+365 -> 42825 | I11: 6328 | J11: =I11/I10-1 -> 0.07072758 | L11: =L10+1 -> 2 | M11: =M10+365 -> 42825 | N11: 17.945756 | O11: =N11/N10-1 -> 0.059558573
B12: =B11+1 -> 3 | C12: =C11+365 -> 43190 | D12: 35545 | E12: =D12/D11-1 -> 0.071859357 | G12: =G11+1 -> 3 | H12: =H11+365 -> 43190 | I12: 7499 | J12: =I12/I11-1 -> 0.18505057 | L12: =L11+1 -> 3 | M12: =M11+365 -> 43190 | N12: 22.517903 | O12: =N12/N11-1 -> 0.25477591
B13: =B12+1 -> 4 | C13: =C12+365 -> 43555 | D13: 39310 | E13: =D13/D12-1 -> 0.10592207 | G13: =G12+1 -> 4 | H13: =H12+365 -> 43555 | I13: 8880 | J13: =I13/I12-1 -> 0.18415789 | L13: =L12+1 -> 4 | M13: =M12+365 -> 43555 | N13: 26.507137 | O13: =N13/N12-1 -> 0.17715836
B14: =B13+1 -> 5 | C14: =C13+365 -> 43920 | D14: 39783 | E14: =D14/D13-1 -> 0.012032562 | G14: =G13+1 -> 5 | H14: =H13+365 -> 43920 | I14: 9861 | J14: =I14/I13-1 -> 0.11047297 | L14: =L13+1 -> 5 | M14: =M13+365 -> 43920 | N14: 29.249815 | O14: =N14/N13-1 -> 0.10346941
B15: =B14+1 -> 6 | C15: =C14+365 -> 44285 | D15: 47028 | E15: =D15/D14-1 -> 0.18211296 | G15: =G14+1 -> 6 | H15: =H14+365 -> 44285 | I15: 11626 | J15: =I15/I14-1 -> 0.17898793 | L15: =L14+1 -> 6 | M15: =M14+365 -> 44285 | N15: 33.320565 | O15: =N15/N14-1 -> 0.13917182
B16: =B15+1 -> 7 | C16: =C15+365 -> 44650 | D16: 52446 | E16: =D16/D15-1 -> 0.11520796 | G16: =G15+1 -> 7 | H16: =H15+365 -> 44650 | I16: 12857 | J16: =I16/I15-1 -> 0.10588336 | L16: =L15+1 -> 7 | M16: =M15+365 -> 44650 | N16: 36.912666 | O16: =N16/N15-1 -> 0.10780432
B17: =B16+1 -> 8 | C17: =C16+365 -> 45015 | D17: 60580 | E17: =D17/D16-1 -> 0.15509286 | G17: =G16+1 -> 8 | H17: =H16+365 -> 45015 | I17: 14147 | J17: =I17/I16-1 -> 0.10033445 | L17: =L16+1 -> 8 | M17: =M16+365 -> 45015 | N17: 41.262343 | O17: =N17/N16-1 -> 0.11783697
B18: =B17+1 -> 9 | C18: =C17+365 -> 45380 | D18: 61896 | E18: =D18/D17-1 -> 0.021723341 | G18: =G17+1 -> 9 | H18: =H17+365 -> 45380 | I18: 14659 | J18: =I18/I17-1 -> 0.036191419 | L18: =L17+1 -> 9 | M18: =M17+365 -> 45380 | N18: 40.283453 | O18: =N18/N17-1 -> -0.023723569
B19: =B18+1 -> 10 | C19: =C18+365 -> 45745 | D19: 63121 | E19: =D19/D18-1 -> 0.019791263 | G19: =G18+1 -> 10 | H19: =H18+365 -> 45745 | I19: 14843 | J19: =I19/I18-1 -> 0.012552016 | L19: =L18+1 -> 10 | M19: =M18+365 -> 45745 | N19: 39.789751 | O19: =N19/N18-1 -> -0.012255679
B20: =B19+1 -> 11 | C20: =C19+365 -> 46110 | D20: =FORECAST(B20,_xlfn.ANCHORARRAY($D$10),$B$10:$B$19) -> 68218.4 | E20: =D20/D19-1 -> 0.080756008 | G20: =G19+1 -> 11 | H20: =H19+365 -> 46110 | I20: =FORECAST(G20,_xlfn.ANCHORARRAY($I$10),$G$10:$G$19) -> 16849.333 | J20: =I20/I19-1 -> 0.13517034 | L20: =L19+1 -> 11 | M20: =M19+365 -> 46110 | N20: =FORECAST(L20,$N$10:$N$19,$L$10:$L$19) -> 46.840909 | O20: =N20/N19-1 -> 0.17721039
B21: =B20+1 -> 12 | C21: =C20+365 -> 46475 | D21: =FORECAST(B21,_xlfn.ANCHORARRAY($D$10),$B$10:$B$19) -> 72166.164 | E21: =D21/D20-1 -> 0.057869484 | G21: =G20+1 -> 12 | H21: =H20+365 -> 46475 | I21: =FORECAST(G21,_xlfn.ANCHORARRAY($I$10),$G$10:$G$19) -> 17974.485 | J21: =I21/I20-1 -> 0.066777213 | L21: =L20+1 -> 12 | M21: =M20+365 -> 46475 | N21: =FORECAST(L21,$N$10:$N$19,$L$10:$L$19) -> 49.816958 | O21: =N21/N20-1 -> 0.063535251
B22: =B21+1 -> 13 | C22: =C21+365 -> 46840 | D22: =FORECAST(B22,_xlfn.ANCHORARRAY($D$10),$B$10:$B$19) -> 76113.927 | E22: =D22/D21-1 -> 0.054703804 | G22: =G21+1 -> 13 | H22: =H21+365 -> 46840 | I22: =FORECAST(G22,_xlfn.ANCHORARRAY($I$10),$G$10:$G$19) -> 19099.636 | J22: =I22/I21-1 -> 0.062597149 | L22: =L21+1 -> 13 | M22: =M21+365 -> 46840 | N22: =FORECAST(L22,$N$10:$N$19,$L$10:$L$19) -> 52.793007 | O22: =N22/N21-1 -> 0.059739675
B23: =B22+1 -> 14 | C23: =C22+365 -> 47205 | D23: =FORECAST(B23,_xlfn.ANCHORARRAY($D$10),$B$10:$B$19) -> 80061.691 | E23: =D23/D22-1 -> 0.051866508 | G23: =G22+1 -> 14 | H23: =H22+365 -> 47205 | I23: =FORECAST(G23,_xlfn.ANCHORARRAY($I$10),$G$10:$G$19) -> 20224.788 | J23: =I23/I22-1 -> 0.058909578 | L23: =L22+1 -> 14 | M23: =M22+365 -> 47205 | N23: =FORECAST(L23,$N$10:$N$19,$L$10:$L$19) -> 55.769056 | O23: =N23/N22-1 -> 0.056372029
B24: =B23+1 -> 15 | C24: =C23+365 -> 47570 | D24: =FORECAST(B24,_xlfn.ANCHORARRAY($D$10),$B$10:$B$19) -> 84009.455 | E24: =D24/D23-1 -> 0.049309021 | G24: =G23+1 -> 15 | H24: =H23+365 -> 47570 | I24: =FORECAST(G24,_xlfn.ANCHORARRAY($I$10),$G$10:$G$19) -> 21349.939 | J24: =I24/I23-1 -> 0.055632302 | L24: =L23+1 -> 15 | M24: =M23+365 -> 47570 | N24: =FORECAST(L24,$N$10:$N$19,$L$10:$L$19) -> 58.745105 | O24: =N24/N23-1 -> 0.053363803

Sheet Intrinsic growth
B1: HINDUSTAN UNILEVER
B5: Calculation of ROIC | E5: ='RAW FS'!J$4 -> 44256 | F5: ='RAW FS'!K$4 -> 44621 | G5: ='RAW FS'!L$4 -> 44986 | H5: ='RAW FS'!M$4 -> 45352 | I5: ='RAW FS'!N$4 -> 45717
B7: Current Assets
B8: ='RAW FS'!B39 -> Inventories | E8: ='RAW FS'!J39 -> 3579 | F8: ='RAW FS'!K39 -> 4096 | G8: ='RAW FS'!L39 -> 4251 | H8: ='RAW FS'!M39 -> 4022 | I8: ='RAW FS'!N39 -> 4415
B9: ='RAW FS'!B40 -> Trade receivables + | E9: ='RAW FS'!J40 -> 1758 | F9: ='RAW FS'!K40 -> 2236 | G9: ='RAW FS'!L40 -> 3079 | H9: ='RAW FS'!M40 -> 2997 | I9: ='RAW FS'!N40 -> 3819
B10: ='RAW FS'!B41 -> Cash Equivalents | E10: ='RAW FS'!J41 -> 4471 | F10: ='RAW FS'!K41 -> 3846 | G10: ='RAW FS'!L41 -> 4678 | H10: ='RAW FS'!M41 -> 7559 | I10: ='RAW FS'!N41 -> 7554
B11: ='RAW FS'!B42 -> Loans n Advances | E11: ='RAW FS'!J42 -> 78 | F11: ='RAW FS'!K42 -> 170 | G11: ='RAW FS'!L42 -> 188 | H11: ='RAW FS'!M42 -> 172 | I11: ='RAW FS'!N42 -> 242
B12: ='RAW FS'!B43 -> Other asset items | E12: ='RAW FS'!J43 -> 3957 | F12: ='RAW FS'!K43 -> 3851 | G12: ='RAW FS'!L43 -> 4189 | H12: ='RAW FS'!M43 -> 4345 | I12: ='RAW FS'!N43 -> 4679
B13: Total Current Assets | E13: =SUM(E8:E12) -> 13843 | F13: =SUM(F8:F12) -> 14199 | G13: =SUM(G8:G12) -> 16385 | H13: =SUM(H8:H12) -> 19095 | I13: =SUM(I8:I12) -> 20709
B15: Current Liabilities
B16: ='RAW FS'!B16 -> Trade Payables | E16: ='RAW FS'!J16 -> 8802 | F16: ='RAW FS'!K16 -> 9068 | G16: ='RAW FS'!L16 -> 9574 | H16: ='RAW FS'!M16 -> 10486 | I16: ='RAW FS'!N16 -> 11315
B17: ='RAW FS'!B17 -> Advance from Customers | E17: ='RAW FS'!J17 -> 96 | F17: ='RAW FS'!K17 -> 119 | G17: ='RAW FS'!L17 -> 98 | H17: ='RAW FS'!M17 -> 91 | I17: ='RAW FS'!N17 -> 105
B18: ='RAW FS'!B18 -> Other liability items | E18: ='RAW FS'!J18 -> 12148 | F18: ='RAW FS'!K18 -> 11189 | G18: ='RAW FS'!L18 -> 11664 | H18: ='RAW FS'!M18 -> 15005 | I18: ='RAW FS'!N18 -> 17186
B19: Total Liabilities | E19: =SUM(E16:E18) -> 21046 | F19: =SUM(F16:F18) -> 20376 | G19: =SUM(G16:G18) -> 21336 | H19: =SUM(H16:H18) -> 25582 | I19: =SUM(I16:I18) -> 28606
A21: # | B21: Net Working Capital | E21: =E13-E19 -> -7203 | F21: =F13-F19 -> -6177 | G21: =G13-G19 -> -4951 | H21: =H13-H19 -> -6487 | I21: =I13-I19 -> -7897
B24: Non Current Assets
B25: ='RAW FS'!B22 -> Land | E25: ='RAW FS'!J22 -> 477 | F25: ='RAW FS'!K22 -> 477 | G25: ='RAW FS'!L22 -> 609 | H25: ='RAW FS'!M22 -> 633 | I25: ='RAW FS'!N22 -> 628
B26: ='RAW FS'!B23 -> Building | E26: ='RAW FS'!J23 -> 2602 | F26: ='RAW FS'!K23 -> 2788 | G26: ='RAW FS'!L23 -> 3101 | H26: ='RAW FS'!M23 -> 3590 | I26: ='RAW FS'!N23 -> 3833
B27: ='RAW FS'!B24 -> Plant Machinery | E27: ='RAW FS'!J24 -> 6097 | F27: ='RAW FS'!K24 -> 6566 | G27: ='RAW FS'!L24 -> 7612 | H27: ='RAW FS'!M24 -> 8946 | I27: ='RAW FS'!N24 -> 9900
B28: ='RAW FS'!B25 -> Equipments | E28: ='RAW FS'!J25 -> 175 | F28: ='RAW FS'!K25 -> 181 | G28: ='RAW FS'!L25 -> 185 | H28: ='RAW FS'!M25 -> 206 | I28: ='RAW FS'!N25 -> 245
B29: ='RAW FS'!B26 -> Furniture n fittings | E29: ='RAW FS'!J26 -> 156 | F29: ='RAW FS'!K26 -> 152 | G29: ='RAW FS'!L26 -> 161 | H29: ='RAW FS'!M26 -> 165 | I29: ='RAW FS'!N26 -> 174
B30: ='RAW FS'!B27 -> Railway sidings | E30: ='RAW FS'!J27 -> 0 | F30: ='RAW FS'!K27 -> 0 | G30: ='RAW FS'!L27 -> 0 | H30: ='RAW FS'!M27 -> 0 | I30: ='RAW FS'!N27 -> 0
B31: ='RAW FS'!B28 -> Vehicles | E31: ='RAW FS'!J28 -> 0 | F31: ='RAW FS'!K28 -> 0 | G31: ='RAW FS'!L28 -> 33 | H31: ='RAW FS'!M28 -> 39 | I31: ='RAW FS'!N28 -> 102
B32: ='RAW FS'!B29 -> Intangible Assets | E32: ='RAW FS'!J29 -> 45262 | F32: ='RAW FS'!K29 -> 45262 | G32: ='RAW FS'!L29 -> 45692 | H32: ='RAW FS'!M29 -> 45692 | I32: ='RAW FS'!N29 -> 45692
B33: ='RAW FS'!B30 -> Other fixed assets | E33: ='RAW FS'!J30 -> 155 | F33: ='RAW FS'!K30 -> 152 | G33: ='RAW FS'!L30 -> 171 | H33: ='RAW FS'!M30 -> 180 | I33: ='RAW FS'!N30 -> 190
B35: ='RAW FS'!B31 -> Gross Block | E35: =SUM(E25:E33) -> 54924 | F35: =SUM(F25:F33) -> 55578 | G35: =SUM(G25:G33) -> 57564 | H35: =SUM(H25:H33) -> 59451 | I35: =SUM(I25:I33) -> 60764
B36: ='RAW FS'!B32 -> Accumulated Depreciation | E36: ='RAW FS'!J32 -> 3481 | F36: ='RAW FS'!K32 -> 4105 | G36: ='RAW FS'!L32 -> 4886 | H36: ='RAW FS'!M32 -> 5707 | I36: ='RAW FS'!N32 -> 6429
B37: ='RAW FS'!B33 -> Net Block | E37: =SUM(E35:E36) -> 58405 | F37: =SUM(F35:F36) -> 59683 | G37: =SUM(G35:G36) -> 62450 | H37: =SUM(H35:H36) -> 65158 | I37: =SUM(I35:I36) -> 67193
A39: # | B39: Invested Capital | E39: =E37+E21 -> 51202 | F39: =F37+F21 -> 53506 | G39: =G37+G21 -> 57499 | H39: =H37+H21 -> 58671 | I39: =I37+I21 -> 59296
B40: EBIT | E40: =Historicals!H22-Historicals!H28 -> 10552 | F40: =Historicals!I22-Historicals!I28 -> 11766 | G40: =Historicals!J22-Historicals!J28 -> 13010 | H40: =Historicals!K22-Historicals!K28 -> 13443 | I40: =Historicals!L22-Historicals!L28 -> 13488
A42: # | B42: ROIC | E42: =E40/E39 -> 0.2060857 | F42: =F40/F39 -> 0.21990057 | G42: =G40/G39 -> 0.2262648 | H42: =H40/H39 -> 0.22912512 | I42: =I40/I39 -> 0.22746897
B45: Calculation of Reinvestment Rate | E45: ='RAW FS'!J$4 -> 44256 | F45: ='RAW FS'!K$4 -> 44621 | G45: ='RAW FS'!L$4 -> 44986 | H45: ='RAW FS'!M$4 -> 45352 | I45: ='RAW FS'!N$4 -> 45717
B47: Net CAPEX | E47: =-1*SUM('Cash Flow Data'!J16:J17) -> 4066 | F47: =-1*SUM('Cash Flow Data'!K16:K17) -> 1053 | G47: =-1*SUM('Cash Flow Data'!L16:L17) -> 1011 | H47: =-1*SUM('Cash Flow Data'!M16:M17) -> 1457 | I47: =-1*SUM('Cash Flow Data'!N16:N17) -> 1262
B48: Change in Working Cap | F48: =F21-E21 -> 1026 | G48: =G21-F21 -> 1226 | H48: =H21-G21 -> -1536 | I48: =I21-H21 -> -1410
B50: EBIT | E50: =E40 -> 10552 | F50: =F40 -> 11766 | G50: =G40 -> 13010 | H50: =H40 -> 13443 | I50: =I40 -> 13488
B51: Tax | E51: 0.25 | F51: 0.25 | G51: 0.25 | H51: 0.25 | I51: 0.25
B52: EBIT(1-t) | E52: =E50*(1-E51) -> 7914 | F52: =F50*(1-F51) -> 8824.5 | G52: =G50*(1-G51) -> 9757.5 | H52: =H50*(1-H51) -> 10082.25 | I52: =I50*(1-I51) -> 10116
B54: Reinvestment | F54: =SUM(F47:F48) -> 2079 | G54: =SUM(G47:G48) -> 2237 | H54: =SUM(H47:H48) -> -79 | I54: =SUM(I47:I48) -> -148
A56: # | B56: Reinvestment Rate | F56: =F54/F52 -> 0.23559408 | G56: =G54/G52 -> 0.22925954 | H56: =H54/H52 -> -0.0078355526 | I56: =I54/I52 -> -0.014630289
G58: 4 Year Average | I58: =AVERAGE(F56:I56) -> 0.11059695
...

Sheet Financials >

Sheet Historicals
B2: HINDUSTAN UNILEVER
B6: ="Historical Financial Statement " &'Data Sheet'!B1 -> Historical Financial Statement HINDUSTAN UNILEVER LTD
B7: Years | C7: ='Data Sheet'!B16 -> 42460 | D7: ='Data Sheet'!C16 -> 42825 | E7: ='Data Sheet'!D16 -> 43190 | F7: ='Data Sheet'!E16 -> 43555 | G7: ='Data Sheet'!F16 -> 43921 | H7: ='Data Sheet'!G16 -> 44286 | I7: ='Data Sheet'!H16 -> 44651 | J7: ='Data Sheet'!I16 -> 45016 | ... L7: ='Data Sheet'!K16 -> 45747 | M7: LTM
A9: # | B9: Income Statement
B10: Sales | C10: =IFERROR('Data Sheet'!B17,0) -> 32186 | D10: =IFERROR('Data Sheet'!C17,0) -> 33162 | E10: =IFERROR('Data Sheet'!D17,0) -> 35545 | F10: =IFERROR('Data Sheet'!E17,0) -> 39310 | G10: =IFERROR('Data Sheet'!F17,0) -> 39783 | H10: =IFERROR('Data Sheet'!G17,0) -> 47028 | I10: =IFERROR('Data Sheet'!H17,0) -> 52446 | J10: =IFERROR('Data Sheet'!I17,0) -> 60580 | ... L10: =IFERROR('Data Sheet'!K17,0) -> 63121 | M10: =IFERROR(SUM('Data Sheet'!H42:K42),0) -> 64544
B11: Sales Growth | D11: =IFERROR((D10/C10-1),0) -> 0.030323743 | E11: =IFERROR((E10/D10-1),0) -> 0.071859357 | F11: =IFERROR((F10/E10-1),0) -> 0.10592207 | G11: =IFERROR((G10/F10-1),0) -> 0.012032562 | H11: =IFERROR((H10/G10-1),0) -> 0.18211296 | I11: =IFERROR((I10/H10-1),0) -> 0.11520796 | J11: =IFERROR((J10/I10-1),0) -> 0.15509286 | K11: =IFERROR((K10/J10-1),0) -> 0.021723341 | ... M11: =IFERROR((M10/L10-1),0) -> 0.022544003
B13: COGS | C13: =IFERROR(SUM('Data Sheet'!B18,'Data Sheet'!B20:B22,-1*('Data Sheet'!B19)),0) -> 18222 | D13: =IFERROR(SUM('Data Sheet'!C18,'Data Sheet'!C20:C22,-1*('Data Sheet'!C19)),0) -> 18675 | E13: =IFERROR(SUM('Data Sheet'!D18,'Data Sheet'!D20:D22,-1*('Data Sheet'!D19)),0) -> 19314 | F13: =IFERROR(SUM('Data Sheet'!E18,'Data Sheet'!E20:E22,-1*('Data Sheet'!E19)),0) -> 21081 | G13: =IFERROR(SUM('Data Sheet'!F18,'Data Sheet'!F20:F22,-1*('Data Sheet'!F19)),0) -> 20614 | H13: =IFERROR(SUM('Data Sheet'!G18,'Data Sheet'!G20:G22,-1*('Data Sheet'!G19)),0) -> 25301 | I13: =IFERROR(SUM('Data Sheet'!H18,'Data Sheet'!H20:H22,-1*('Data Sheet'!H19)),0) -> 29066 | J13: =IFERROR(SUM('Data Sheet'!I18,'Data Sheet'!I20:I22,-1*('Data Sheet'!I19)),0) -> 35381 | ... M13: =IFERROR(SUM('Data Sheet'!L18,'Data Sheet'!L20:L22,-1*('Data Sheet'!L19)),0) -> 0
B14: COGS % SALES | C14: =IFERROR(C13/C10,0) -> 0.56614677 | D14: =IFERROR(D13/D10,0) -> 0.56314456 | E14: =IFERROR(E13/E10,0) -> 0.54336756 | F14: =IFERROR(F13/F10,0) -> 0.53627576 | G14: =IFERROR(G13/G10,0) -> 0.51816102 | H14: =IFERROR(H13/H10,0) -> 0.53799864 | I14: =IFERROR(I13/I10,0) -> 0.55420814 | J14: =IFERROR(J13/J10,0) -> 0.58403764 | ... M14: =IFERROR(M13/M10,0) -> 0
B16: GROSS PROFIT | C16: =IFERROR(C10-C13,0) -> 13964 | D16: =IFERROR(D10-D13,0) -> 14487 | E16: =IFERROR(E10-E13,0) -> 16231 | F16: =IFERROR(F10-F13,0) -> 18229 | G16: =IFERROR(G10-G13,0) -> 19169 | H16: =IFERROR(H10-H13,0) -> 21727 | I16: =IFERROR(I10-I13,0) -> 23380 | J16: =IFERROR(J10-J13,0) -> 25199 | ... M16: =IFERROR(M10-M13,0) -> 64544
B17: GROSS MARGIN | C17: =C16/C10 -> 0.43385323 | D17: =D16/D10 -> 0.43685544 | E17: =E16/E10 -> 0.45663244 | F17: =F16/F10 -> 0.46372424 | G17: =G16/G10 -> 0.48183898 | H17: =H16/H10 -> 0.46200136 | I17: =I16/I10 -> 0.44579186 | J17: =J16/J10 -> 0.41596236 | ... M17: =M16/M10 -> 1
B19: SALES AND ADMISTRATIVE EXPENSES | C19: =IFERROR(SUM('Data Sheet'!B23:B24),0) -> 8054 | D19: =IFERROR(SUM('Data Sheet'!C23:C24),0) -> 8159 | E19: =IFERROR(SUM('Data Sheet'!D23:D24),0) -> 8732 | F19: =IFERROR(SUM('Data Sheet'!E23:E24),0) -> 9349 | G19: =IFERROR(SUM('Data Sheet'!F23:F24),0) -> 9308 | H19: =IFERROR(SUM('Data Sheet'!G23:G24),0) -> 10101 | I19: =IFERROR(SUM('Data Sheet'!H23:H24),0) -> 10523 | J19: =IFERROR(SUM('Data Sheet'!I23:I24),0) -> 11052 | ... M19: =IFERROR(SUM('Data Sheet'!L23:L24),0) -> 0
B20: S&A EXP % SALES | C20: =C19/C10 -> 0.25023302 | D20: =D19/D10 -> 0.24603462 | E20: =E19/E10 -> 0.24566043 | F20: =F19/F10 -> 0.23782752 | G20: =G19/G10 -> 0.23396928 | H20: =H19/H10 -> 0.21478694 | I20: =I19/I10 -> 0.20064447 | J20: =J19/J10 -> 0.18243645 | ... M20: =M19/M10 -> 0
B22: EBITDA | C22: =IFERROR(C16-C19,0) -> 5910 | D22: =IFERROR(D16-D19,0) -> 6328 | E22: =IFERROR(E16-E19,0) -> 7499 | F22: =IFERROR(F16-F19,0) -> 8880 | G22: =IFERROR(G16-G19,0) -> 9861 | H22: =IFERROR(H16-H19,0) -> 11626 | I22: =IFERROR(I16-I19,0) -> 12857 | J22: =IFERROR(J16-J19,0) -> 14147 | ... M22: =IFERROR(M16-M19,0) -> 64544
B23: EBITDA MARGIN | C23: =C22/C10 -> 0.18362021 | D23: =D22/D10 -> 0.19082082 | E23: =E22/E10 -> 0.21097201 | F23: =F22/F10 -> 0.22589672 | G23: =G22/G10 -> 0.24786969 | H23: =H22/H10 -> 0.24721443 | I23: =I22/I10 -> 0.24514739 | J23: =J22/J10 -> 0.23352592 | ... M23: =M22/M10 -> 1
B25: INTEREST | C25: =IFERROR('Data Sheet'!B27,0) -> 17 | D25: =IFERROR('Data Sheet'!C27,0) -> 35 | E25: =IFERROR('Data Sheet'!D27,0) -> 26 | F25: =IFERROR('Data Sheet'!E27,0) -> 33 | G25: =IFERROR('Data Sheet'!F27,0) -> 118 | H25: =IFERROR('Data Sheet'!G27,0) -> 117 | I25: =IFERROR('Data Sheet'!H27,0) -> 106 | J25: =IFERROR('Data Sheet'!I27,0) -> 114 | ... L25: =IFERROR('Data Sheet'!K27,0) -> 395 | M25: =IFERROR(SUM('Data Sheet'!H46:K46),0) -> 419
B26: INTEREST % SALES | C26: =C25/C10 -> 0.00052817995 | D26: =D25/D10 -> 0.0010554249 | E26: =E25/E10 -> 0.00073146715 | F26: =F25/F10 -> 0.00083948105 | G26: =G25/G10 -> 0.002966091 | H26: =H25/H10 -> 0.0024878796 | I26: =I25/I10 -> 0.0020211265 | J26: =J25/J10 -> 0.0018818092 | ... M26: =M25/M10 -> 0.0064916956
B28: DEPRICIATION | C28: =IFERROR('Data Sheet'!B26,0) -> 353 | D28: =IFERROR('Data Sheet'!C26,0) -> 432 | E28: =IFERROR('Data Sheet'!D26,0) -> 520 | F28: =IFERROR('Data Sheet'!E26,0) -> 565 | G28: =IFERROR('Data Sheet'!F26,0) -> 1002 | H28: =IFERROR('Data Sheet'!G26,0) -> 1074 | I28: =IFERROR('Data Sheet'!H26,0) -> 1091 | J28: =IFERROR('Data Sheet'!I26,0) -> 1137 | ... L28: =IFERROR('Data Sheet'!K26,0) -> 1355 | M28: =IFERROR(SUM('Data Sheet'!H45:K45),0) -> 1367
B29: DEPRICIATION % SALES | C29: =C28/C10 -> 0.010967501 | D29: =D28/D10 -> 0.013026959 | E29: =E28/E10 -> 0.014629343 | F29: =F28/F10 -> 0.014372933 | G29: =G28/G10 -> 0.025186638 | H29: =H28/H10 -> 0.022837459 | I29: =I28/I10 -> 0.020802349 | J29: =J28/J10 -> 0.01876857 | ... M29: =M28/M10 -> 0.021179351
B31: PROFIT BEFORE TAX | C31: =IFERROR(C22-SUM(C25,C28),0) -> 5540 | D31: =IFERROR(D22-SUM(D25,D28),0) -> 5861 | E31: =IFERROR(E22-SUM(E25,E28),0) -> 6953 | F31: =IFERROR(F22-SUM(F25,F28),0) -> 8282 | G31: =IFERROR(G22-SUM(G25,G28),0) -> 8741 | H31: =IFERROR(H22-SUM(H25,H28),0) -> 10435 | I31: =IFERROR(I22-SUM(I25,I28),0) -> 11660 | J31: =IFERROR(J22-SUM(J25,J28),0) -> 12896 | ... M31: =IFERROR(M22-SUM(M25,M28),0) -> 62758
B32: PBT MARGIN | C32: =C31/C10 -> 0.17212453 | D32: =D31/D10 -> 0.17673844 | E32: =E31/E10 -> 0.1956112 | F32: =F31/F10 -> 0.2106843 | G32: =G31/G10 -> 0.21971696 | H32: =H31/H10 -> 0.22188909 | I32: =I31/I10 -> 0.22232391 | J32: =J31/J10 -> 0.21287554 | ... M32: =M31/M10 -> 0.97232895
B34: TAX PAID | C34: =IFERROR('Data Sheet'!B29,0) -> 1875 | D34: =IFERROR('Data Sheet'!C29,0) -> 1977 | E34: =IFERROR('Data Sheet'!D29,0) -> 2079 | F34: =IFERROR('Data Sheet'!E29,0) -> 2544 | G34: =IFERROR('Data Sheet'!F29,0) -> 2409 | H34: =IFERROR('Data Sheet'!G29,0) -> 2606 | I34: =IFERROR('Data Sheet'!H29,0) -> 2987 | J34: =IFERROR('Data Sheet'!I29,0) -> 3201 | ... L34: =IFERROR('Data Sheet'!K29,0) -> 3744 | M34: =IFERROR(SUM('Data Sheet'!H48:K48),0) -> 3134
B35: EFFECTIVE TAX RATE | C35: =C34/C31 -> 0.33844765 | D35: =D34/D31 -> 0.33731445 | E35: =E34/E31 -> 0.29900762 | F35: =F34/F31 -> 0.30717218 | G35: =G34/G31 -> 0.27559776 | H35: =H34/H31 -> 0.24973646 | I35: =I34/I31 -> 0.25617496 | J35: =J34/J31 -> 0.2482165 | ... M35: =M34/M31 -> 0.049937857
B37: NET PROFIT | C37: =C31-C34 -> 3665 | D37: =D31-D34 -> 3884 | E37: =E31-E34 -> 4874 | F37: =F31-F34 -> 5738 | G37: =G31-G34 -> 6332 | H37: =H31-H34 -> 7829 | I37: =I31-I34 -> 8673 | J37: =J31-J34 -> 9695 | ... M37: =M31-M34 -> 59624
B38: NP MARGIN | C38: =C37/C10 -> 0.11386938 | D38: =D37/D10 -> 0.11712201 | E38: =E37/E10 -> 0.13712196 | F38: =F37/F10 -> 0.14596795 | G38: =G37/G10 -> 0.15916346 | H38: =H37/H10 -> 0.16647529 | I38: =I37/I10 -> 0.16537009 | J38: =J37/J10 -> 0.16003632 | ... M38: =M37/M10 -> 0.92377293
B40: No. of Equity Shares | C40: ='Data Sheet'!B93 -> 216.39 | D40: ='Data Sheet'!C93 -> 216.43 | E40: ='Data Sheet'!D93 -> 216.45 | F40: ='Data Sheet'!E93 -> 216.47 | G40: ='Data Sheet'!F93 -> 216.48 | H40: ='Data Sheet'!G93 -> 234.96 | I40: ='Data Sheet'!H93 -> 234.96 | J40: ='Data Sheet'!I93 -> 234.96 | ... L40: ='Data Sheet'!K93 -> 234.96 | M40: =L40 -> 234.96
B42: EPS | C42: =IFERROR(C37/C40,0) -> 16.937012 | D42: =IFERROR(D37/D40,0) -> 17.945756 | E42: =IFERROR(E37/E40,0) -> 22.517903 | F42: =IFERROR(F37/F40,0) -> 26.507137 | G42: =IFERROR(G37/G40,0) -> 29.249815 | H42: =IFERROR(H37/H40,0) -> 33.320565 | I42: =IFERROR(I37/I40,0) -> 36.912666 | J42: =IFERROR(J37/J40,0) -> 41.262343 | ... M42: =IFERROR(M37/M40,0) -> 253.76234
B43: EPS % growth | D43: =IFERROR(D42/C42-1,0) -> 0.059558573 | E43: =IFERROR(E42/D42-1,0) -> 0.25477591 | F43: =IFERROR(F42/E42-1,0) -> 0.17715836 | G43: =IFERROR(G42/F42-1,0) -> 0.10346941 | H43: =IFERROR(H42/G42-1,0) -> 0.13917182 | I43: =IFERROR(I42/H42-1,0) -> 0.10780432 | J43: =IFERROR(J42/I42-1,0) -> 0.11783697 | K43: =IFERROR(K42/J42-1,0) -> -0.023723569 | ... M43: =IFERROR(M42/L42-1,0) -> 5.3775805
B45: DIVIDEND PER SHARE | C45: =IFERROR('Data Sheet'!B31/Historicals!C40,0) -> 15.971163 | D45: =IFERROR('Data Sheet'!C31/Historicals!D40,0) -> 16.966225 | E45: =IFERROR('Data Sheet'!D31/Historicals!E40,0) -> 19.95842 | F45: =IFERROR('Data Sheet'!E31/Historicals!F40,0) -> 21.952234 | G45: =IFERROR('Data Sheet'!F31/Historicals!G40,0) -> 24.944568 | H45: =IFERROR('Data Sheet'!G31/Historicals!H40,0) -> 40.506895 | I45: =IFERROR('Data Sheet'!H31/Historicals!I40,0) -> 34.005788 | J45: =IFERROR('Data Sheet'!I31/Historicals!J40,0) -> 39.006639 | ... M45: =IFERROR('Data Sheet'!L31/Historicals!M40,0) -> 0
B46: DIVIDEND PAYOUT RATIO | C46: =C45/C42 -> 0.94297408 | D46: =D45/D42 -> 0.9454171 | E46: =E45/E42 -> 0.88633566 | F46: =F45/F42 -> 0.82816312 | G46: =G45/G42 -> 0.85281112 | H46: =H45/H42 -> 1.2156725 | I46: =I45/I42 -> 0.92124986 | J46: =J45/J42 -> 0.94533265 | ... M46: =M45/M42 -> 0
B48: RETAINED EARNINGS | C48: =1-C46 -> 0.057025921 | D48: =1-D46 -> 0.054582904 | E48: =1-E46 -> 0.11366434 | F48: =1-F46 -> 0.17183688 | G48: =1-G46 -> 0.14718888 | H48: =1-H46 -> -0.2156725 | I48: =1-I46 -> 0.078750144 | J48: =1-J46 -> 0.054667354 | ... M48: =1-M46 -> 1
A51: # | B51: Balance Sheet
B53: Equity Share Capital | C53: =IFERROR('Data Sheet'!B57,0) -> 216 | D53: =IFERROR('Data Sheet'!C57,0) -> 216 | E53: =IFERROR('Data Sheet'!D57,0) -> 216 | F53: =IFERROR('Data Sheet'!E57,0) -> 216 | G53: =IFERROR('Data Sheet'!F57,0) -> 216 | H53: =IFERROR('Data Sheet'!G57,0) -> 235 | I53: =IFERROR('Data Sheet'!H57,0) -> 235 | J53: =IFERROR('Data Sheet'!I57,0) -> 235 | ... L53: =IFERROR('Data Sheet'!K57,0) -> 235
B54: Reserves | C54: =IFERROR('Data Sheet'!B58,0) -> 6357 | D54: =IFERROR('Data Sheet'!C58,0) -> 6528 | E54: =IFERROR('Data Sheet'!D58,0) -> 7065 | F54: =IFERROR('Data Sheet'!E58,0) -> 7651 | G54: =IFERROR('Data Sheet'!F58,0) -> 8013 | H54: =IFERROR('Data Sheet'!G58,0) -> 47439 | I54: =IFERROR('Data Sheet'!H58,0) -> 48826 | J54: =IFERROR('Data Sheet'!I58,0) -> 50069 | ... L54: =IFERROR('Data Sheet'!K58,0) -> 49167
B55: Borrowings | C55: =IFERROR('Data Sheet'!B59,0) -> 177 | D55: =IFERROR('Data Sheet'!C59,0) -> 277 | E55: =IFERROR('Data Sheet'!D59,0) -> 0 | F55: =IFERROR('Data Sheet'!E59,0) -> 99 | G55: =IFERROR('Data Sheet'!F59,0) -> 0 | H55: =IFERROR('Data Sheet'!G59,0) -> 0 | I55: =IFERROR('Data Sheet'!H59,0) -> 1043 | J55: =IFERROR('Data Sheet'!I59,0) -> 1219 | ... L55: =IFERROR('Data Sheet'!K59,0) -> 1648
B56: Other Liabilities | C56: =IFERROR('Data Sheet'!B60,0) -> 8043 | D56: =IFERROR('Data Sheet'!C60,0) -> 8685 | E56: =IFERROR('Data Sheet'!D60,0) -> 10581 | F56: =IFERROR('Data Sheet'!E60,0) -> 10663 | G56: =IFERROR('Data Sheet'!F60,0) -> 11924 | H56: =IFERROR('Data Sheet'!G60,0) -> 21066 | I56: =IFERROR('Data Sheet'!H60,0) -> 20402 | J56: =IFERROR('Data Sheet'!I60,0) -> 21554 | ... L56: =IFERROR('Data Sheet'!K60,0) -> 28813
B57: Total | C57: =IFERROR('Data Sheet'!B61,0) -> 14793 | D57: =IFERROR('Data Sheet'!C61,0) -> 15706 | E57: =IFERROR('Data Sheet'!D61,0) -> 17862 | F57: =IFERROR('Data Sheet'!E61,0) -> 18629 | G57: =IFERROR('Data Sheet'!F61,0) -> 20153 | H57: =IFERROR('Data Sheet'!G61,0) -> 68740 | I57: =IFERROR('Data Sheet'!H61,0) -> 70506 | J57: =IFERROR('Data Sheet'!I61,0) -> 73077 | ... L57: =IFERROR('Data Sheet'!K61,0) -> 79863
B59: Fixed Assets Net Block | C59: =IFERROR('Data Sheet'!B62,0) -> 3258 | D59: =IFERROR('Data Sheet'!C62,0) -> 4419 | E59: =IFERROR('Data Sheet'!D62,0) -> 4528 | F59: =IFERROR('Data Sheet'!E62,0) -> 4715 | G59: =IFERROR('Data Sheet'!F62,0) -> 5479 | H59: =IFERROR('Data Sheet'!G62,0) -> 51443 | I59: =IFERROR('Data Sheet'!H62,0) -> 51473 | J59: =IFERROR('Data Sheet'!I62,0) -> 52678 | ... L59: =IFERROR('Data Sheet'!K62,0) -> 54335
B60: Capital Work in Progress | C60: =IFERROR('Data Sheet'!B63,0) -> 408 | D60: =IFERROR('Data Sheet'!C63,0) -> 229 | E60: =IFERROR('Data Sheet'!D63,0) -> 461 | F60: =IFERROR('Data Sheet'!E63,0) -> 406 | G60: =IFERROR('Data Sheet'!F63,0) -> 597 | H60: =IFERROR('Data Sheet'!G63,0) -> 745 | I60: =IFERROR('Data Sheet'!H63,0) -> 1313 | J60: =IFERROR('Data Sheet'!I63,0) -> 1132 | ... L60: =IFERROR('Data Sheet'!K63,0) -> 1009
B61: Investments | C61: =IFERROR('Data Sheet'!B64,0) -> 2592 | D61: =IFERROR('Data Sheet'!C64,0) -> 3794 | E61: =IFERROR('Data Sheet'!D64,0) -> 2873 | F61: =IFERROR('Data Sheet'!E64,0) -> 2716 | G61: =IFERROR('Data Sheet'!F64,0) -> 1255 | H61: =IFERROR('Data Sheet'!G64,0) -> 2709 | I61: =IFERROR('Data Sheet'!H64,0) -> 3521 | J61: =IFERROR('Data Sheet'!I64,0) -> 2882 | ... L61: =IFERROR('Data Sheet'!K64,0) -> 3810
B62: Other Assets | C62: =IFERROR('Data Sheet'!B65-SUM(C65:C67),0) -> 1536 | D62: =IFERROR('Data Sheet'!C65-SUM(D65:D67),0) -> 1810 | E62: =IFERROR('Data Sheet'!D65-SUM(E65:E67),0) -> 2692 | F62: =IFERROR('Data Sheet'!E65-SUM(F65:F67),0) -> 2645 | G62: =IFERROR('Data Sheet'!F65-SUM(G65:G67),0) -> 3793 | H62: =IFERROR('Data Sheet'!G65-SUM(H65:H67),0) -> 4035 | I62: =IFERROR('Data Sheet'!H65-SUM(I65:I67),0) -> 4021 | J62: =IFERROR('Data Sheet'!I65-SUM(J65:J67),0) -> 4377 | ... L62: =IFERROR('Data Sheet'!K65-SUM(L65:L67),0) -> 4921
...

Sheet Common Size
B1: HINDUSTAN UNILEVER
B5: ="Common Size Statement - " &'Data Sheet'!$B$1 -> Common Size Statement - HINDUSTAN UNILEVER LTD
B6: Years | C6: ='Data Sheet'!B16 -> 42460 | D6: ='Data Sheet'!C16 -> 42825 | E6: ='Data Sheet'!D16 -> 43190 | F6: ='Data Sheet'!E16 -> 43555 | G6: ='Data Sheet'!F16 -> 43921 | H6: ='Data Sheet'!G16 -> 44286 | I6: ='Data Sheet'!H16 -> 44651 | J6: ='Data Sheet'!I16 -> 45016 | ... L6: ='Data Sheet'!K16 -> 45747
A8: # | B8: ="Common Size Income statement - " &'Data Sheet'!$B$1 -> Common Size Income statement - HINDUSTAN UNILEVER LTD
B10: Sales | C10: ='Data Sheet'!B17/'Data Sheet'!B$17 -> 1 | D10: ='Data Sheet'!C17/'Data Sheet'!C$17 -> 1 | E10: ='Data Sheet'!D17/'Data Sheet'!D$17 -> 1 | F10: ='Data Sheet'!E17/'Data Sheet'!E$17 -> 1 | G10: ='Data Sheet'!F17/'Data Sheet'!F$17 -> 1 | H10: ='Data Sheet'!G17/'Data Sheet'!G$17 -> 1 | I10: ='Data Sheet'!H17/'Data Sheet'!H$17 -> 1 | J10: ='Data Sheet'!I17/'Data Sheet'!I$17 -> 1 | ... L10: ='Data Sheet'!K17/'Data Sheet'!K$17 -> 1
B11: Raw Material Cost | C11: ='Data Sheet'!B18/'Data Sheet'!B$17 -> 0.40961909 | D11: ='Data Sheet'!C18/'Data Sheet'!C$17 -> 0.41028888 | E11: ='Data Sheet'!D18/'Data Sheet'!D$17 -> 0.400422 | F11: ='Data Sheet'!E18/'Data Sheet'!E$17 -> 0.4030781 | G11: ='Data Sheet'!F18/'Data Sheet'!F$17 -> 0.39456552 | H11: ='Data Sheet'!G18/'Data Sheet'!G$17 -> 0.42827677 | I11: ='Data Sheet'!H18/'Data Sheet'!H$17 -> 0.43608664 | J11: ='Data Sheet'!I18/'Data Sheet'!I$17 -> 0.46924728 | ... L11: ='Data Sheet'!K18/'Data Sheet'!K$17 -> 0.43319973
B12: Change in Inventory | C12: ='Data Sheet'!B19/'Data Sheet'!B$17 -> -0.002578761 | D12: ='Data Sheet'!C19/'Data Sheet'!C$17 -> -0.0043423195 | E12: ='Data Sheet'!D19/'Data Sheet'!D$17 -> 0.0020256014 | F12: ='Data Sheet'!E19/'Data Sheet'!E$17 -> -0.00030526584 | G12: ='Data Sheet'!F19/'Data Sheet'!F$17 -> 0.0027147274 | H12: ='Data Sheet'!G19/'Data Sheet'!G$17 -> 0.0086118908 | I12: ='Data Sheet'!H19/'Data Sheet'!H$17 -> 0.00041947908 | J12: ='Data Sheet'!I19/'Data Sheet'!I$17 -> 0.0012380324 | ... L12: ='Data Sheet'!K19/'Data Sheet'!K$17 -> 0.002423916
B13: Power and Fuel | C13: ='Data Sheet'!B20/'Data Sheet'!B$17 -> 0.0096004474 | D13: ='Data Sheet'!C20/'Data Sheet'!C$17 -> 0.008895724 | E13: ='Data Sheet'!D20/'Data Sheet'!D$17 -> 0.0082993389 | F13: ='Data Sheet'!E20/'Data Sheet'!E$17 -> 0.0078351564 | G13: ='Data Sheet'!F20/'Data Sheet'!F$17 -> 0.0075157731 | H13: ='Data Sheet'!G20/'Data Sheet'!G$17 -> 0.0072084715 | I13: ='Data Sheet'!H20/'Data Sheet'!H$17 -> 0.0060633795 | J13: ='Data Sheet'!I20/'Data Sheet'!I$17 -> 0.0063387257 | ... L13: ='Data Sheet'!K20/'Data Sheet'!K$17 -> 0.0067647851
B14: Other Mfr. Exp | C14: ='Data Sheet'!B21/'Data Sheet'!B$17 -> 0.092151867 | D14: ='Data Sheet'!C21/'Data Sheet'!C$17 -> 0.087057475 | E14: ='Data Sheet'!D21/'Data Sheet'!D$17 -> 0.08434379 | F14: ='Data Sheet'!E21/'Data Sheet'!E$17 -> 0.077359451 | G14: ='Data Sheet'!F21/'Data Sheet'!F$17 -> 0.073046276 | H14: ='Data Sheet'!G21/'Data Sheet'!G$17 -> 0.060984945 | I14: ='Data Sheet'!H21/'Data Sheet'!H$17 -> 0.063951493 | J14: ='Data Sheet'!I21/'Data Sheet'!I$17 -> 0.062578409 | ... L14: ='Data Sheet'!K21/'Data Sheet'!K$17 -> 0.060740483
B15: Employee Cost | C15: ='Data Sheet'!B22/'Data Sheet'!B$17 -> 0.052196607 | D15: ='Data Sheet'!C22/'Data Sheet'!C$17 -> 0.052560159 | E15: ='Data Sheet'!D22/'Data Sheet'!D$17 -> 0.052328035 | F15: ='Data Sheet'!E22/'Data Sheet'!E$17 -> 0.047697787 | G15: ='Data Sheet'!F22/'Data Sheet'!F$17 -> 0.045748184 | H15: ='Data Sheet'!G22/'Data Sheet'!G$17 -> 0.050140342 | I15: ='Data Sheet'!H22/'Data Sheet'!H$17 -> 0.048526103 | J15: ='Data Sheet'!I22/'Data Sheet'!I$17 -> 0.047111258 | ... L15: ='Data Sheet'!K22/'Data Sheet'!K$17 -> 0.048747643
B16: Selling and admin | C16: ='Data Sheet'!B23/'Data Sheet'!B$17 -> 0.20943889 | D16: ='Data Sheet'!C23/'Data Sheet'!C$17 -> 0.20170677 | E16: ='Data Sheet'!D23/'Data Sheet'!D$17 -> 0.20402307 | F16: ='Data Sheet'!E23/'Data Sheet'!E$17 -> 0.19832104 | G16: ='Data Sheet'!F23/'Data Sheet'!F$17 -> 0.1915391 | H16: ='Data Sheet'!G23/'Data Sheet'!G$17 -> 0.16811261 | I16: ='Data Sheet'!H23/'Data Sheet'!H$17 -> 0.15566487 | J16: ='Data Sheet'!I23/'Data Sheet'!I$17 -> 0.14501486 | ... L16: ='Data Sheet'!K23/'Data Sheet'!K$17 -> 0.16940479
B17: Other Expenses | C17: ='Data Sheet'!B24/'Data Sheet'!B$17 -> 0.040794134 | D17: ='Data Sheet'!C24/'Data Sheet'!C$17 -> 0.044327845 | E17: ='Data Sheet'!D24/'Data Sheet'!D$17 -> 0.041637361 | F17: ='Data Sheet'!E24/'Data Sheet'!E$17 -> 0.039506487 | G17: ='Data Sheet'!F24/'Data Sheet'!F$17 -> 0.042430184 | H17: ='Data Sheet'!G24/'Data Sheet'!G$17 -> 0.046674322 | I17: ='Data Sheet'!H24/'Data Sheet'!H$17 -> 0.044979598 | J17: ='Data Sheet'!I24/'Data Sheet'!I$17 -> 0.037421591 | ... L17: ='Data Sheet'!K24/'Data Sheet'!K$17 -> 0.048414949
B18: Other Income | C18: ='Data Sheet'!B25/'Data Sheet'!B$17 -> 0.015099733 | D18: ='Data Sheet'!C25/'Data Sheet'!C$17 -> 0.018273928 | E18: ='Data Sheet'!D25/'Data Sheet'!D$17 -> 0.0099310733 | F18: ='Data Sheet'!E25/'Data Sheet'!E$17 -> 0.0081912999 | G18: ='Data Sheet'!F25/'Data Sheet'!F$17 -> 0.010657819 | H18: ='Data Sheet'!G25/'Data Sheet'!G$17 -> 0.0036148677 | I18: ='Data Sheet'!H25/'Data Sheet'!H$17 -> 0.0041757236 | J18: ='Data Sheet'!I25/'Data Sheet'!I$17 -> 0.0073951799 | ... L18: ='Data Sheet'!K25/'Data Sheet'!K$17 -> 0.020943901
B19: Depreciation | C19: ='Data Sheet'!B26/'Data Sheet'!B$17 -> 0.010967501 | D19: ='Data Sheet'!C26/'Data Sheet'!C$17 -> 0.013026959 | E19: ='Data Sheet'!D26/'Data Sheet'!D$17 -> 0.014629343 | F19: ='Data Sheet'!E26/'Data Sheet'!E$17 -> 0.014372933 | G19: ='Data Sheet'!F26/'Data Sheet'!F$17 -> 0.025186638 | H19: ='Data Sheet'!G26/'Data Sheet'!G$17 -> 0.022837459 | I19: ='Data Sheet'!H26/'Data Sheet'!H$17 -> 0.020802349 | J19: ='Data Sheet'!I26/'Data Sheet'!I$17 -> 0.01876857 | ... L19: ='Data Sheet'!K26/'Data Sheet'!K$17 -> 0.021466707
B20: Interest | C20: ='Data Sheet'!B27/'Data Sheet'!B$17 -> 0.00052817995 | D20: ='Data Sheet'!C27/'Data Sheet'!C$17 -> 0.0010554249 | E20: ='Data Sheet'!D27/'Data Sheet'!D$17 -> 0.00073146715 | F20: ='Data Sheet'!E27/'Data Sheet'!E$17 -> 0.00083948105 | G20: ='Data Sheet'!F27/'Data Sheet'!F$17 -> 0.002966091 | H20: ='Data Sheet'!G27/'Data Sheet'!G$17 -> 0.0024878796 | I20: ='Data Sheet'!H27/'Data Sheet'!H$17 -> 0.0020211265 | J20: ='Data Sheet'!I27/'Data Sheet'!I$17 -> 0.0018818092 | ... L20: ='Data Sheet'!K27/'Data Sheet'!K$17 -> 0.0062578223
B21: Profit before tax | C21: ='Data Sheet'!B28/'Data Sheet'!B$17 -> 0.18722426 | D21: ='Data Sheet'!C28/'Data Sheet'!C$17 -> 0.19501236 | E21: ='Data Sheet'!D28/'Data Sheet'!D$17 -> 0.20554227 | F21: ='Data Sheet'!E28/'Data Sheet'!E$17 -> 0.2188756 | G21: ='Data Sheet'!F28/'Data Sheet'!F$17 -> 0.23037478 | H21: ='Data Sheet'!G28/'Data Sheet'!G$17 -> 0.22550396 | I21: ='Data Sheet'!H28/'Data Sheet'!H$17 -> 0.22649964 | J21: ='Data Sheet'!I28/'Data Sheet'!I$17 -> 0.22027072 | ... L21: ='Data Sheet'!K28/'Data Sheet'!K$17 -> 0.22837091
B22: Net profit | C22: ='Data Sheet'!B30/'Data Sheet'!B$17 -> 0.12896912 | D22: ='Data Sheet'!C30/'Data Sheet'!C$17 -> 0.13497377 | E22: ='Data Sheet'!D30/'Data Sheet'!D$17 -> 0.1466873 | F22: ='Data Sheet'!E30/'Data Sheet'!E$17 -> 0.15400661 | G22: ='Data Sheet'!F30/'Data Sheet'!F$17 -> 0.16962019 | H22: ='Data Sheet'!G30/'Data Sheet'!G$17 -> 0.1700051 | I22: ='Data Sheet'!H30/'Data Sheet'!H$17 -> 0.16929794 | J22: ='Data Sheet'!I30/'Data Sheet'!I$17 -> 0.16705183 | ... L22: ='Data Sheet'!K30/'Data Sheet'!K$17 -> 0.16870772
B23: Dividend Amount | C23: ='Data Sheet'!B31/'Data Sheet'!B$17 -> 0.10737588 | D23: ='Data Sheet'!C31/'Data Sheet'!C$17 -> 0.11072915 | E23: ='Data Sheet'!D31/'Data Sheet'!D$17 -> 0.12153608 | F23: ='Data Sheet'!E31/'Data Sheet'!E$17 -> 0.12088527 | G23: ='Data Sheet'!F31/'Data Sheet'!F$17 -> 0.13573637 | H23: ='Data Sheet'!G31/'Data Sheet'!G$17 -> 0.20237943 | I23: ='Data Sheet'!H31/'Data Sheet'!H$17 -> 0.15234718 | J23: ='Data Sheet'!I31/'Data Sheet'!I$17 -> 0.15128755 | ... L23: ='Data Sheet'!K31/'Data Sheet'!K$17 -> 0.19731943
A25: # | B25: ="Common Size Balance Sheet - " &'Data Sheet'!$B$1 -> Common Size Balance Sheet - HINDUSTAN UNILEVER LTD
B27: Total Liabilites | C27: ='Data Sheet'!B61/'Data Sheet'!B$61 -> 1 | D27: ='Data Sheet'!C61/'Data Sheet'!C$61 -> 1 | E27: ='Data Sheet'!D61/'Data Sheet'!D$61 -> 1 | F27: ='Data Sheet'!E61/'Data Sheet'!E$61 -> 1 | G27: ='Data Sheet'!F61/'Data Sheet'!F$61 -> 1 | H27: ='Data Sheet'!G61/'Data Sheet'!G$61 -> 1 | I27: ='Data Sheet'!H61/'Data Sheet'!H$61 -> 1 | J27: ='Data Sheet'!I61/'Data Sheet'!I$61 -> 1 | ... L27: ='Data Sheet'!K61/'Data Sheet'!K$61 -> 1
B29: Equity Share Capital | C29: ='Data Sheet'!B57/'Data Sheet'!B$61 -> 0.014601501 | D29: ='Data Sheet'!C57/'Data Sheet'!C$61 -> 0.013752706 | E29: ='Data Sheet'!D57/'Data Sheet'!D$61 -> 0.012092711 | F29: ='Data Sheet'!E57/'Data Sheet'!E$61 -> 0.011594825 | G29: ='Data Sheet'!F57/'Data Sheet'!F$61 -> 0.010718007 | H29: ='Data Sheet'!G57/'Data Sheet'!G$61 -> 0.0034186791 | I29: ='Data Sheet'!H57/'Data Sheet'!H$61 -> 0.0033330497 | J29: ='Data Sheet'!I57/'Data Sheet'!I$61 -> 0.0032157861 | ... L29: ='Data Sheet'!K57/'Data Sheet'!K$61 -> 0.0029425391
B30: Reserves | C30: ='Data Sheet'!B58/'Data Sheet'!B$61 -> 0.42973028 | D30: ='Data Sheet'!C58/'Data Sheet'!C$61 -> 0.41563734 | E30: ='Data Sheet'!D58/'Data Sheet'!D$61 -> 0.39553242 | F30: ='Data Sheet'!E58/'Data Sheet'!E$61 -> 0.41070374 | G30: ='Data Sheet'!F58/'Data Sheet'!F$61 -> 0.3976083 | H30: ='Data Sheet'!G58/'Data Sheet'!G$61 -> 0.6901222 | I30: ='Data Sheet'!H58/'Data Sheet'!H$61 -> 0.69250844 | J30: ='Data Sheet'!I58/'Data Sheet'!I$61 -> 0.68515402 | ... L30: ='Data Sheet'!K58/'Data Sheet'!K$61 -> 0.61564179
B31: Borrowings | C31: ='Data Sheet'!B59/'Data Sheet'!B$61 -> 0.011965119 | D31: ='Data Sheet'!C59/'Data Sheet'!C$61 -> 0.017636572 | E31: ='Data Sheet'!D59/'Data Sheet'!D$61 -> 0 | F31: ='Data Sheet'!E59/'Data Sheet'!E$61 -> 0.0053142949 | G31: ='Data Sheet'!F59/'Data Sheet'!F$61 -> 0 | H31: ='Data Sheet'!G59/'Data Sheet'!G$61 -> 0 | I31: ='Data Sheet'!H59/'Data Sheet'!H$61 -> 0.014793067 | J31: ='Data Sheet'!I59/'Data Sheet'!I$61 -> 0.016681035 | ... L31: ='Data Sheet'!K59/'Data Sheet'!K$61 -> 0.020635338
B32: Other Liabilities | C32: ='Data Sheet'!B60/'Data Sheet'!B$61 -> 0.5437031 | D32: ='Data Sheet'!C60/'Data Sheet'!C$61 -> 0.55297339 | E32: ='Data Sheet'!D60/'Data Sheet'!D$61 -> 0.59237487 | F32: ='Data Sheet'!E60/'Data Sheet'!E$61 -> 0.57238714 | G32: ='Data Sheet'!F60/'Data Sheet'!F$61 -> 0.5916737 | H32: ='Data Sheet'!G60/'Data Sheet'!G$61 -> 0.30645912 | I32: ='Data Sheet'!H60/'Data Sheet'!H$61 -> 0.28936544 | J32: ='Data Sheet'!I60/'Data Sheet'!I$61 -> 0.29494916 | ... L32: ='Data Sheet'!K60/'Data Sheet'!K$61 -> 0.36078034
B34: Total Assets | C34: =C44+C40 -> 1 | D34: =D44+D40 -> 1 | E34: =E44+E40 -> 1 | F34: =F44+F40 -> 1 | G34: =G44+G40 -> 1 | H34: =H44+H40 -> 1 | I34: =I44+I40 -> 1 | J34: =J44+J40 -> 1 | ... L34: =L44+L40 -> 1
B36: Net Block | C36: ='Data Sheet'!B62/'Data Sheet'!B$66 -> 0.2202393 | D36: ='Data Sheet'!C62/'Data Sheet'!C$66 -> 0.28135744 | E36: ='Data Sheet'!D62/'Data Sheet'!D$66 -> 0.25349905 | F36: ='Data Sheet'!E62/'Data Sheet'!E$66 -> 0.25310001 | G36: ='Data Sheet'!F62/'Data Sheet'!F$66 -> 0.27187019 | H36: ='Data Sheet'!G62/'Data Sheet'!G$66 -> 0.74837067 | I36: ='Data Sheet'!H62/'Data Sheet'!H$66 -> 0.73005134 | J36: ='Data Sheet'!I62/'Data Sheet'!I$66 -> 0.72085608 | ... L36: ='Data Sheet'!K62/'Data Sheet'!K$66 -> 0.6803526
B37: Capital Work in Progress | C37: ='Data Sheet'!B63/'Data Sheet'!B$66 -> 0.027580612 | D37: ='Data Sheet'!C63/'Data Sheet'!C$66 -> 0.014580415 | E37: ='Data Sheet'!D63/'Data Sheet'!D$66 -> 0.02580898 | F37: ='Data Sheet'!E63/'Data Sheet'!E$66 -> 0.021793977 | G37: ='Data Sheet'!F63/'Data Sheet'!F$66 -> 0.029623381 | H37: ='Data Sheet'!G63/'Data Sheet'!G$66 -> 0.01083794 | I37: ='Data Sheet'!H63/'Data Sheet'!H$66 -> 0.018622529 | J37: ='Data Sheet'!I63/'Data Sheet'!I$66 -> 0.01549051 | ... L37: ='Data Sheet'!K63/'Data Sheet'!K$66 -> 0.012634136
B38: Investments | C38: ='Data Sheet'!B64/'Data Sheet'!B$66 -> 0.17521801 | D38: ='Data Sheet'!C64/'Data Sheet'!C$66 -> 0.24156373 | E38: ='Data Sheet'!D64/'Data Sheet'!D$66 -> 0.16084425 | F38: ='Data Sheet'!E64/'Data Sheet'!E$66 -> 0.14579419 | G38: ='Data Sheet'!F64/'Data Sheet'!F$66 -> 0.062273607 | H38: ='Data Sheet'!G64/'Data Sheet'!G$66 -> 0.039409369 | I38: ='Data Sheet'!H64/'Data Sheet'!H$66 -> 0.049939012 | J38: ='Data Sheet'!I64/'Data Sheet'!I$66 -> 0.039437853 | ... L38: ='Data Sheet'!K64/'Data Sheet'!K$66 -> 0.047706698
B39: Other Assets | C39: =('Data Sheet'!B65-SUM('Data Sheet'!B67:B69))/'Data Sheet'!B$66 -> 0.10383289 | D39: =('Data Sheet'!C65-SUM('Data Sheet'!C67:C69))/'Data Sheet'!C$66 -> 0.11524258 | E39: =('Data Sheet'!D65-SUM('Data Sheet'!D67:D69))/'Data Sheet'!D$66 -> 0.15071101 | F39: =('Data Sheet'!E65-SUM('Data Sheet'!E67:E69))/'Data Sheet'!E$66 -> 0.14198293 | G39: =('Data Sheet'!F65-SUM('Data Sheet'!F67:F69))/'Data Sheet'!F$66 -> 0.18821019 | H39: =('Data Sheet'!G65-SUM('Data Sheet'!G67:G69))/'Data Sheet'!G$66 -> 0.058699447 | I39: =('Data Sheet'!H65-SUM('Data Sheet'!H67:H69))/'Data Sheet'!H$66 -> 0.057030607 | J39: =('Data Sheet'!I65-SUM('Data Sheet'!I67:I69))/'Data Sheet'!I$66 -> 0.059895726 | ... L39: =('Data Sheet'!K65-SUM('Data Sheet'!K67:K69))/'Data Sheet'!K$66 -> 0.061618021
B40: Total Non Current Assets | C40: =SUM(C36:C39) -> 0.52687082 | D40: =SUM(D36:D39) -> 0.65274417 | E40: =SUM(E36:E39) -> 0.59086329 | F40: =SUM(F36:F39) -> 0.5626711 | G40: =SUM(G36:G39) -> 0.55197737 | H40: =SUM(H36:H39) -> 0.85731743 | I40: =SUM(I36:I39) -> 0.85564349 | J40: =SUM(J36:J39) -> 0.83568017 | ... L40: =SUM(L36:L39) -> 0.80231146
B41: Receivables | C41: ='Data Sheet'!B67/'Data Sheet'!B$66 -> 0.085445819 | D41: ='Data Sheet'!C67/'Data Sheet'!C$66 -> 0.06908188 | E41: ='Data Sheet'!D67/'Data Sheet'!D$66 -> 0.073340052 | F41: ='Data Sheet'!E67/'Data Sheet'!E$66 -> 0.09748242 | G41: ='Data Sheet'!F67/'Data Sheet'!F$66 -> 0.057013844 | H41: ='Data Sheet'!G67/'Data Sheet'!G$66 -> 0.025574629 | I41: ='Data Sheet'!H67/'Data Sheet'!H$66 -> 0.031713613 | J41: ='Data Sheet'!I67/'Data Sheet'!I$66 -> 0.04213364 | ... L41: ='Data Sheet'!K67/'Data Sheet'!K$66 -> 0.047819391
B42: Inventory | C42: ='Data Sheet'!B68/'Data Sheet'!B$66 -> 0.18427635 | D42: ='Data Sheet'!C68/'Data Sheet'!C$66 -> 0.1617853 | E42: ='Data Sheet'!D68/'Data Sheet'!D$66 -> 0.14068973 | F42: ='Data Sheet'!E68/'Data Sheet'!E$66 -> 0.13817167 | G42: ='Data Sheet'!F68/'Data Sheet'!F$66 -> 0.13729966 | H42: ='Data Sheet'!G68/'Data Sheet'!G$66 -> 0.052065755 | I42: ='Data Sheet'!H68/'Data Sheet'!H$66 -> 0.058094347 | J42: ='Data Sheet'!I68/'Data Sheet'!I$66 -> 0.058171518 | ... L42: ='Data Sheet'!K68/'Data Sheet'!K$66 -> 0.055282171
B43: Cash & Bank | C43: ='Data Sheet'!B69/'Data Sheet'!B$66 -> 0.20340702 | D43: ='Data Sheet'!C69/'Data Sheet'!C$66 -> 0.11638864 | E43: ='Data Sheet'!D69/'Data Sheet'!D$66 -> 0.19510693 | F43: ='Data Sheet'!E69/'Data Sheet'!E$66 -> 0.20167481 | G43: ='Data Sheet'!F69/'Data Sheet'!F$66 -> 0.25370913 | H43: ='Data Sheet'!G69/'Data Sheet'!G$66 -> 0.065042188 | I43: ='Data Sheet'!H69/'Data Sheet'!H$66 -> 0.054548549 | J43: ='Data Sheet'!I69/'Data Sheet'!I$66 -> 0.064014669 | ... L43: ='Data Sheet'!K69/'Data Sheet'!K$66 -> 0.09458698
B44: Total Current Assets | C44: =SUM('Data Sheet'!B67:B69)/'Data Sheet'!B66 -> 0.47312918 | D44: =SUM('Data Sheet'!C67:C69)/'Data Sheet'!C66 -> 0.34725583 | E44: =SUM('Data Sheet'!D67:D69)/'Data Sheet'!D66 -> 0.40913671 | F44: =SUM('Data Sheet'!E67:E69)/'Data Sheet'!E66 -> 0.4373289 | G44: =SUM('Data Sheet'!F67:F69)/'Data Sheet'!F66 -> 0.44802263 | H44: =SUM('Data Sheet'!G67:G69)/'Data Sheet'!G66 -> 0.14268257 | I44: =SUM('Data Sheet'!H67:H69)/'Data Sheet'!H66 -> 0.14435651 | J44: =SUM('Data Sheet'!I67:I69)/'Data Sheet'!I66 -> 0.16431983 | ... L44: =SUM('Data Sheet'!K67:K69)/'Data Sheet'!K66 -> 0.19768854

Sheet Ratio Analysis
B1: HINDUSTAN UNILEVER
B5: ="Ratio Analysis - " &'Data Sheet'!B1 -> Ratio Analysis - HINDUSTAN UNILEVER LTD
B6: Years | C6: ='Data Sheet'!B16 -> 42460 | D6: ='Data Sheet'!C16 -> 42825 | E6: ='Data Sheet'!D16 -> 43190 | F6: ='Data Sheet'!E16 -> 43555 | G6: ='Data Sheet'!F16 -> 43921 | H6: ='Data Sheet'!G16 -> 44286 | I6: ='Data Sheet'!H16 -> 44651 | J6: ='Data Sheet'!I16 -> 45016 | ... L6: ='Data Sheet'!K16 -> 45747 | M6: Trend | N6: MEAN | O6: MEDIAN
B8: Sales Growth | D8: =IFERROR(Historicals!D11,0) -> 0.030323743 | E8: =IFERROR(Historicals!E11,0) -> 0.071859357 | F8: =IFERROR(Historicals!F11,0) -> 0.10592207 | G8: =IFERROR(Historicals!G11,0) -> 0.012032562 | H8: =IFERROR(Historicals!H11,0) -> 0.18211296 | I8: =IFERROR(Historicals!I11,0) -> 0.11520796 | J8: =IFERROR(Historicals!J11,0) -> 0.15509286 | K8: =IFERROR(Historicals!K11,0) -> 0.021723341 | L8: =IFERROR(Historicals!L11,0) -> 0.019791263 | N8: =IFERROR(AVERAGE(D8:L8),0) -> 0.07934068 | O8: =IFERROR(MEDIAN(D8:L8),0) -> 0.071859357
B9: EBITDA Growth | D9: =IFERROR(Historicals!D22/Historicals!C22-1,0) -> 0.07072758 | E9: =IFERROR(Historicals!E22/Historicals!D22-1,0) -> 0.18505057 | F9: =IFERROR(Historicals!F22/Historicals!E22-1,0) -> 0.18415789 | G9: =IFERROR(Historicals!G22/Historicals!F22-1,0) -> 0.11047297 | H9: =IFERROR(Historicals!H22/Historicals!G22-1,0) -> 0.17898793 | I9: =IFERROR(Historicals!I22/Historicals!H22-1,0) -> 0.10588336 | J9: =IFERROR(Historicals!J22/Historicals!I22-1,0) -> 0.10033445 | K9: =IFERROR(Historicals!K22/Historicals!J22-1,0) -> 0.036191419 | L9: =IFERROR(Historicals!L22/Historicals!K22-1,0) -> 0.012552016 | N9: =IFERROR(AVERAGE(D9:L9),0) -> 0.10937313 | O9: =IFERROR(MEDIAN(D9:L9),0) -> 0.10588336
B10: EBIT Growth | D10: =IFERROR((Historicals!D22-Historicals!D28)/(Historicals!C22-Historicals!C28)-1,0) -> 0.061004139 | E10: =IFERROR((Historicals!E22-Historicals!E28)/(Historicals!D22-Historicals!D28)-1,0) -> 0.18368385 | F10: =IFERROR((Historicals!F22-Historicals!F28)/(Historicals!E22-Historicals!E28)-1,0) -> 0.19143144 | G10: =IFERROR((Historicals!G22-Historicals!G28)/(Historicals!F22-Historicals!F28)-1,0) -> 0.065423933 | H10: =IFERROR((Historicals!H22-Historicals!H28)/(Historicals!G22-Historicals!G28)-1,0) -> 0.19110509 | I10: =IFERROR((Historicals!I22-Historicals!I28)/(Historicals!H22-Historicals!H28)-1,0) -> 0.11504928 | J10: =IFERROR((Historicals!J22-Historicals!J28)/(Historicals!I22-Historicals!I28)-1,0) -> 0.10572837 | K10: =IFERROR((Historicals!K22-Historicals!K28)/(Historicals!J22-Historicals!J28)-1,0) -> 0.033282091 | L10: =IFERROR((Historicals!L22-Historicals!L28)/(Historicals!K22-Historicals!K28)-1,0) -> 0.0033474671 | N10: =IFERROR(AVERAGE(D10:L10),0) -> 0.10556174 | O10: =IFERROR(MEDIAN(D10:L10),0) -> 0.10572837
B11: EBT Growth | D11: =IFERROR(Historicals!D31/Historicals!C31-1,0) -> 0.057942238 | E11: =IFERROR(Historicals!E31/Historicals!D31-1,0) -> 0.18631633 | F11: =IFERROR(Historicals!F31/Historicals!E31-1,0) -> 0.19114051 | G11: =IFERROR(Historicals!G31/Historicals!F31-1,0) -> 0.055421396 | H11: =IFERROR(Historicals!H31/Historicals!G31-1,0) -> 0.19379934 | I11: =IFERROR(Historicals!I31/Historicals!H31-1,0) -> 0.11739339 | J11: =IFERROR(Historicals!J31/Historicals!I31-1,0) -> 0.10600343 | K11: =IFERROR(Historicals!K31/Historicals!J31-1,0) -> 0.016516749 | L11: =IFERROR(Historicals!L31/Historicals!K31-1,0) -> -0.0012205355 | N11: =IFERROR(AVERAGE(D11:L11),0) -> 0.10259032 | O11: =IFERROR(MEDIAN(D11:L11),0) -> 0.10600343
B12: PAT Growth | D12: =IFERROR(Historicals!D37/Historicals!C37-1,0) -> 0.059754434 | E12: =IFERROR(Historicals!E37/Historicals!D37-1,0) -> 0.25489186 | F12: =IFERROR(Historicals!F37/Historicals!E37-1,0) -> 0.17726713 | G12: =IFERROR(Historicals!G37/Historicals!F37-1,0) -> 0.10352039 | H12: =IFERROR(Historicals!H37/Historicals!G37-1,0) -> 0.23641819 | I12: =IFERROR(Historicals!I37/Historicals!H37-1,0) -> 0.10780432 | J12: =IFERROR(Historicals!J37/Historicals!I37-1,0) -> 0.11783697 | K12: =IFERROR(Historicals!K37/Historicals!J37-1,0) -> -0.023723569 | L12: =IFERROR(Historicals!L37/Historicals!K37-1,0) -> -0.012255679 | N12: =IFERROR(AVERAGE(D12:L12),0) -> 0.11350156 | O12: =IFERROR(MEDIAN(D12:L12),0) -> 0.10780432
B13: Dividend Growth | D13: =IFERROR(Historicals!D45/Historicals!C45-1,0) -> 0.062303632 | E13: =IFERROR(Historicals!E45/Historicals!D45-1,0) -> 0.17636188 | F13: =IFERROR(Historicals!F45/Historicals!E45-1,0) -> 0.099898369 | G13: =IFERROR(Historicals!G45/Historicals!F45-1,0) -> 0.13631114 | H13: =IFERROR(Historicals!H45/Historicals!G45-1,0) -> 0.6238764 | I13: =IFERROR(Historicals!I45/Historicals!H45-1,0) -> -0.16049383 | J13: =IFERROR(Historicals!J45/Historicals!I45-1,0) -> 0.14705882 | K13: =IFERROR(Historicals!K45/Historicals!J45-1,0) -> 0.076923077 | L13: =IFERROR(Historicals!L45/Historicals!K45-1,0) -> 0.26190476 | N13: =IFERROR(AVERAGE(D13:L13),0) -> 0.15823825 | O13: =IFERROR(MEDIAN(D13:L13),0) -> 0.13631114
